<?xml version="1.0" encoding="utf-8"?><testsuites><testsuite errors="1" failures="1" hostname="liqingMacBook-Pro.local" name="pytest" skipped="0" tests="2" time="36.335" timestamp="2020-03-25T22:16:36.994724"><testcase classname="test_case.test_weather_condition.TestWeatherCondition" file="test_case/test_weather_condition.py" line="24" name="test_weather_desc_equal" time="26.108"><failure message="AttributeError: &apos;NoneType&apos; object has no attribute &apos;find_element_by_id&apos;">self = &lt;test_case.test_weather_condition.TestWeatherCondition object at 0x109c6c5f8&gt;
browser = None

    def test_weather_desc_equal(self, browser):
        &quot;&quot;&quot;
        judge weather_desc in main page and condition page
        :param browser:
        :return:
        &quot;&quot;&quot;
        self.weather_condition_business = WeatherCompareBusiness(browser)
        print(&quot;hello&quot;)
&gt;       assert self.weather_condition_business.compare_weather()

test_case/test_weather_condition.py:33: 
_ _ _ _ _ _ _ _ _ _ _ _ _ _ _ _ _ _ _ _ _ _ _ _ _ _ _ _ _ _ _ _ _ _ _ _ _ _ _ _ 
bussiness/weather_compare_bussiness.py:23: in compare_weather
    weather_desc = self.weather_handle.get_weather_desc()
handle/weather_handle.py:28: in get_weather_desc
    return self.weather_page.get_condition().text
_ _ _ _ _ _ _ _ _ _ _ _ _ _ _ _ _ _ _ _ _ _ _ _ _ _ _ _ _ _ _ _ _ _ _ _ _ _ _ _ 

self = &lt;page.weather_page.WeatherPage object at 0x109c6ca20&gt;

    def get_condition(self):
&gt;       return self.driver.find_element_by_id(&quot;com.moji.mjweather:id/tv_weather_des&quot;)
E       AttributeError: &apos;NoneType&apos; object has no attribute &apos;find_element_by_id&apos;

page/weather_page.py:22: AttributeError</failure></testcase><testcase time="2.470"></testcase><testcase classname="pytest" name="internal" time="0.000"><error message="internal error">Traceback (most recent call last):
  File &quot;/Library/Frameworks/Python.framework/Versions/3.6/lib/python3.6/site-packages/_pytest/main.py&quot;, line 193, in wrap_session
    session.exitstatus = doit(config, session) or 0
  File &quot;/Library/Frameworks/Python.framework/Versions/3.6/lib/python3.6/site-packages/_pytest/main.py&quot;, line 237, in _main
    config.hook.pytest_runtestloop(session=session)
  File &quot;/Library/Frameworks/Python.framework/Versions/3.6/lib/python3.6/site-packages/pluggy/hooks.py&quot;, line 286, in __call__
    return self._hookexec(self, self.get_hookimpls(), kwargs)
  File &quot;/Library/Frameworks/Python.framework/Versions/3.6/lib/python3.6/site-packages/pluggy/manager.py&quot;, line 92, in _hookexec
    return self._inner_hookexec(hook, methods, kwargs)
  File &quot;/Library/Frameworks/Python.framework/Versions/3.6/lib/python3.6/site-packages/pluggy/manager.py&quot;, line 86, in &lt;lambda&gt;
    firstresult=hook.spec.opts.get(&quot;firstresult&quot;) if hook.spec else False,
  File &quot;/Library/Frameworks/Python.framework/Versions/3.6/lib/python3.6/site-packages/pluggy/callers.py&quot;, line 208, in _multicall
    return outcome.get_result()
  File &quot;/Library/Frameworks/Python.framework/Versions/3.6/lib/python3.6/site-packages/pluggy/callers.py&quot;, line 80, in get_result
    raise ex[1].with_traceback(ex[2])
  File &quot;/Library/Frameworks/Python.framework/Versions/3.6/lib/python3.6/site-packages/pluggy/callers.py&quot;, line 187, in _multicall
    res = hook_impl.function(*args)
  File &quot;/Library/Frameworks/Python.framework/Versions/3.6/lib/python3.6/site-packages/_pytest/main.py&quot;, line 258, in pytest_runtestloop
    item.config.hook.pytest_runtest_protocol(item=item, nextitem=nextitem)
  File &quot;/Library/Frameworks/Python.framework/Versions/3.6/lib/python3.6/site-packages/pluggy/hooks.py&quot;, line 286, in __call__
    return self._hookexec(self, self.get_hookimpls(), kwargs)
  File &quot;/Library/Frameworks/Python.framework/Versions/3.6/lib/python3.6/site-packages/pluggy/manager.py&quot;, line 92, in _hookexec
    return self._inner_hookexec(hook, methods, kwargs)
  File &quot;/Library/Frameworks/Python.framework/Versions/3.6/lib/python3.6/site-packages/pluggy/manager.py&quot;, line 86, in &lt;lambda&gt;
    firstresult=hook.spec.opts.get(&quot;firstresult&quot;) if hook.spec else False,
  File &quot;/Library/Frameworks/Python.framework/Versions/3.6/lib/python3.6/site-packages/pluggy/callers.py&quot;, line 208, in _multicall
    return outcome.get_result()
  File &quot;/Library/Frameworks/Python.framework/Versions/3.6/lib/python3.6/site-packages/pluggy/callers.py&quot;, line 80, in get_result
    raise ex[1].with_traceback(ex[2])
  File &quot;/Library/Frameworks/Python.framework/Versions/3.6/lib/python3.6/site-packages/pluggy/callers.py&quot;, line 187, in _multicall
    res = hook_impl.function(*args)
  File &quot;/Library/Frameworks/Python.framework/Versions/3.6/lib/python3.6/site-packages/pytest_rerunfailures.py&quot;, line 200, in pytest_runtest_protocol
    reports = runtestprotocol(item, nextitem=nextitem, log=False)
  File &quot;/Library/Frameworks/Python.framework/Versions/3.6/lib/python3.6/site-packages/_pytest/runner.py&quot;, line 89, in runtestprotocol
    rep = call_and_report(item, &quot;setup&quot;, log)
  File &quot;/Library/Frameworks/Python.framework/Versions/3.6/lib/python3.6/site-packages/_pytest/runner.py&quot;, line 178, in call_and_report
    report = hook.pytest_runtest_makereport(item=item, call=call)
  File &quot;/Library/Frameworks/Python.framework/Versions/3.6/lib/python3.6/site-packages/pluggy/hooks.py&quot;, line 286, in __call__
    return self._hookexec(self, self.get_hookimpls(), kwargs)
  File &quot;/Library/Frameworks/Python.framework/Versions/3.6/lib/python3.6/site-packages/pluggy/manager.py&quot;, line 92, in _hookexec
    return self._inner_hookexec(hook, methods, kwargs)
  File &quot;/Library/Frameworks/Python.framework/Versions/3.6/lib/python3.6/site-packages/pluggy/manager.py&quot;, line 86, in &lt;lambda&gt;
    firstresult=hook.spec.opts.get(&quot;firstresult&quot;) if hook.spec else False,
  File &quot;/Library/Frameworks/Python.framework/Versions/3.6/lib/python3.6/site-packages/pluggy/callers.py&quot;, line 203, in _multicall
    gen.send(outcome)
  File &quot;/Users/qing.li/PycharmProjects/moji_ui_app/conftest.py&quot;, line 30, in pytest_runtest_makereport
    screen_img = _capture_screenshot()
  File &quot;/Users/qing.li/PycharmProjects/moji_ui_app/conftest.py&quot;, line 45, in _capture_screenshot
    return driver.get_screenshot_as_base64()
  File &quot;/Library/Frameworks/Python.framework/Versions/3.6/lib/python3.6/site-packages/selenium/webdriver/remote/webdriver.py&quot;, line 1074, in get_screenshot_as_base64
    return self.execute(Command.SCREENSHOT)[&apos;value&apos;]
  File &quot;/Library/Frameworks/Python.framework/Versions/3.6/lib/python3.6/site-packages/selenium/webdriver/remote/webdriver.py&quot;, line 321, in execute
    self.error_handler.check_response(response)
  File &quot;/Library/Frameworks/Python.framework/Versions/3.6/lib/python3.6/site-packages/appium/webdriver/errorhandler.py&quot;, line 29, in check_response
    raise wde
  File &quot;/Library/Frameworks/Python.framework/Versions/3.6/lib/python3.6/site-packages/appium/webdriver/errorhandler.py&quot;, line 24, in check_response
    super(MobileErrorHandler, self).check_response(response)
  File &quot;/Library/Frameworks/Python.framework/Versions/3.6/lib/python3.6/site-packages/selenium/webdriver/remote/errorhandler.py&quot;, line 242, in check_response
    raise exception_class(message, screen, stacktrace)
selenium.common.exceptions.InvalidSessionIdException: Message: A session is either terminated or not started</error></testcase></testsuite></testsuites>